<?xml version="1.0" encoding="UTF-8"?>
<!-- Generated by org.testng.reporters.JUnitXMLReporter -->
<testsuite ignored="3" hostname="DESKTOP-AAMQG5Q" failures="1" tests="3" name="smokeTest" time="0.377" errors="0" timestamp="2025-07-15T19:04:19 IST">
  <testcase classname="testngDemo.TestngDemo" name="retryTestDemo" time="0.052">
    <skipped/>
  </testcase> <!-- retryTestDemo -->
  <testcase classname="testngDemo.TestngDemo" name="retryTestDemo" time="0.002">
    <skipped/>
  </testcase> <!-- retryTestDemo -->
  <testcase classname="testngDemo.TestngDemo" name="retryTestDemo" time="0.001">
    <failure type="java.lang.AssertionError" message="expected [3] but found [2]">
      <![CDATA[java.lang.AssertionError: expected [3] but found [2]
at testngDemo.TestngDemo.retryTestDemo(TestngDemo.java:51)
at java.base/java.util.ArrayList.forEach(ArrayList.java:1511)
... Removed 34 stack frames]]>
    </failure>
  </testcase> <!-- retryTestDemo -->
  <testcase classname="testngDemo.TestngDemo" name="demo1" time="0.0">
    <ignored/>
  </testcase> <!-- demo1 -->
  <testcase classname="testngDemo.TestngDemo" name="demo2" time="0.0">
    <ignored/>
  </testcase> <!-- demo2 -->
  <testcase classname="testngDemo.TestngDemo" name="demo3" time="0.0">
    <ignored/>
  </testcase> <!-- demo3 -->
</testsuite> <!-- smokeTest -->
